from asyncio import events



def _set_task_name(task, name):
    if name is not None:
        try:
            set_name = task.set_name
        except AttributeError:
            pass
        else:
            set_name(name)

__all__ = 'run',

from asyncio import coroutines
from asyncio import events
from asyncio import tasks



import asyncio

async def test(main):
       loop = events.get_running_loop()
       task = loop.create_task(main)
       _set_task_name(task, name = None)
       return task
    


def run(main, *, debug=None):
   
    
    main = test(main)


    
    if events._get_running_loop() is not None:
        raise RuntimeError(
            "asyncio.run() cannot be called from a running event loop")

    if not coroutines.iscoroutine(main):
        raise ValueError("a coroutine was expected, got {!r}".format(main))

    loop = events.new_event_loop()
    try:
        events.set_event_loop(loop)
        if debug is not None:
            loop.set_debug(debug)
        return loop.run_until_complete(main)
    finally:
        try:
            _cancel_all_tasks(loop)
            loop.run_until_complete(loop.shutdown_asyncgens())
            loop.run_until_complete(loop.shutdown_default_executor())
        finally:
            events.set_event_loop(None)
            loop.close()


def _cancel_all_tasks(loop):
    to_cancel = tasks.all_tasks(loop)
    if not to_cancel:
        return

    for task in to_cancel:
        task.cancel()

    loop.run_until_complete(tasks.gather(*to_cancel, return_exceptions=True))

    for task in to_cancel:
        if task.cancelled():
            continue
        if task.exception() is not None:
            loop.call_exception_handler({
                'message': 'unhandled exception during asyncio.run() shutdown',
                'exception': task.exception(),
                'task': task,
            })
